Workbook

Sheet Inputs
A1: HAVANA CLEANING — EDITABLE INPUTS
A2: Yellow cells are editable — all other sheets calculate from these values.
A4: SERVICE PRICING
A5: Residential Cleaning | B5: 120 | C5: Base price (2-bed/1-bath)
A6: Deep Clean | B6: 220 | C6: Full deep clean
A7: Move-In/Move-Out | B7: 280 | C7: Complete move clean
A8: Post-Construction | B8: 350 | C8: Debris & dust removal
A9: Airbnb Turnover | B9: 150 | C9: Quick turnaround
A10: Green Clean | B10: 140 | C10: Eco-friendly products
A11: Recurring Plans | B11: 100 | C11: Discounted recurring
A12: Commercial (Monthly Contract) | B12: 2500 | C12: Custom quote average
A13: Avg Add-On Price | B13: 35 | C13: Per add-on service
A14: Add-On Attach Rate | B14: 0.4 | C14: % of non-commercial jobs
A16: LABOR RATES & HOURS
A17: Entry-Level Cleaner ($/hr) | B17: 20 | C17: Starting rate
A18: Senior Cleaner ($/hr) | B18: 25 | C18: 2+ years experience
A19: Team Lead ($/hr) | B19: 28 | C19: Supervisory role
A20: Part-Time Admin ($/hr) | B20: 18 | C20: Scheduling & phones
A21: Part-Time Bookkeeper ($/hr) | B21: 22 | C21: Accounting support
A22: Cleaner Hours/Month | B22: 156 | C22: 26 days x 6 productive hrs
A23: Admin Hours/Month | B23: 80 | C23: Part-time ~20 hrs/week
A24: Bookkeeper Hours/Month | B24: 40 | C24: Part-time ~10 hrs/week
A25: Working Days/Month | B25: 26 | C25: Mon-Sat
A26: Owner Draw Year 1 | B26: 0 | C26: Reinvesting Year 1
A27: Owner Draw Year 2 | B27: 45000 | C27: Annual
A28: Owner Draw Year 3 | B28: 60000 | C28: Annual
A30: PAYROLL BURDEN
A31: Payroll Tax Rate (FICA) | B31: 0.0765 | C31: Social Security + Medicare
A32: Workers Comp Rate | B32: 0.045 | C32: FL cleaning industry avg
A33: Benefits per FT Employee/Mo | B33: 200 | C33: Basic health stipend
A35: VEHICLE & OPERATIONS
A36: Gas Cost per Day per Vehicle | B36: 25 | C36: Avg 60 miles/day
A37: Vehicle Insurance/Month | B37: 300 | C37: Per vehicle
A38: Vehicle Maintenance/Month | B38: 150 | C38: Per vehicle
A39: Vehicle Parking & Tolls/Month | B39: 50 | C39: Per vehicle
A40: Vehicles Year 1 (end) | B40: 1
A41: Vehicles Year 2 | B41: 2
A42: Vehicles Year 3 | B42: 3
A43: Supply Cost per Std Job | B43: 8.5 | C43: Consumable supplies
A44: Supply Cost per Deep Job | B44: 14 | C44: More product usage
...

Sheet Startup Costs
A1: HAVANA CLEANING — STARTUP COSTS BREAKDOWN
A2: Edit QTY and UNIT COST (yellow) — totals auto-calculate.
A4: CATEGORY | B4: ITEM | C4: QTY | D4: UNIT COST | E4: TOTAL COST
A5: CLEANING EQUIPMENT
B6: Commercial Vacuum Cleaner (Backpack) | C6: 3 | D6: 350 | E6: =C6*D6
B7: Commercial Mop & Bucket System | C7: 3 | D7: 85 | E7: =C7*D7
B8: Microfiber Flat Mop System | C8: 3 | D8: 65 | E8: =C8*D8
B9: Spray Bottles (set of 6) | C9: 4 | D9: 18 | E9: =C9*D9
B10: Telescoping Extension Pole | C10: 3 | D10: 35 | E10: =C10*D10
B11: Scrub Brush Set (multiple sizes) | C11: 4 | D11: 22 | E11: =C11*D11
B12: Squeegee Set (windows) | C12: 3 | D12: 28 | E12: =C12*D12
B13: Dusting Kit (feather duster, microfiber) | C13: 4 | D13: 32 | E13: =C13*D13
B14: Toilet Brush & Caddy Set | C14: 6 | D14: 12 | E14: =C14*D14
B15: Grout Brush Set | C15: 4 | D15: 15 | E15: =C15*D15
B16: Detail Cleaning Brush Kit | C16: 4 | D16: 18 | E16: =C16*D16
B17: Step Ladder (3-step, lightweight) | C17: 2 | D17: 75 | E17: =C17*D17
... B22: Trash Grabber/Picker Tool | C22: 3 | D22: 15 | E22: =C22*D22
A23: CLEANING SUPPLIES (3-Month Stock)
B24: All-Purpose Cleaner (gallon concentrate) | C24: 12 | D24: 18 | E24: =C24*D24
B25: Glass Cleaner (gallon concentrate) | C25: 8 | D25: 15 | E25: =C25*D25
B26: Disinfectant Spray (gallon concentrate) | C26: 10 | D26: 22 | E26: =C26*D26
B27: Toilet Bowl Cleaner (bottles) | C27: 24 | D27: 5.75 | E27: =C27*D27
B28: Stainless Steel Cleaner | C28: 8 | D28: 9 | E28: =C28*D28
B29: Wood Floor Cleaner (gallon) | C29: 6 | D29: 14 | E29: =C29*D29
B30: Tile & Grout Cleaner (gallon) | C30: 6 | D30: 16 | E30: =C30*D30
B31: Degreaser (kitchen, gallon) | C31: 6 | D31: 18 | E31: =C31*D31
B32: Microfiber Cloths (packs of 24) | C32: 8 | D32: 22 | E32: =C32*D32
B33: Sponges (packs of 12) | C33: 10 | D33: 8 | E33: =C33*D33
B34: Magic Eraser Pads (packs of 10) | C34: 8 | D34: 12 | E34: =C34*D34
B35: Steel Wool Pads (fine grade, box) | C35: 6 | D35: 7 | E35: =C35*D35
... B43: Air Freshener Spray (bottles) | C43: 12 | D43: 6 | E43: =C43*D43
A44: GREEN CLEAN PRODUCT LINE
B45: Eco-Friendly All-Purpose Cleaner (gallon) | C45: 6 | D45: 24 | E45: =C45*D45
B46: Plant-Based Disinfectant (gallon) | C46: 4 | D46: 28 | E46: =C46*D46
B47: Non-Toxic Glass Cleaner (gallon) | C47: 4 | D47: 20 | E47: =C47*D47
B48: Biodegradable Trash Bags (box of 100) | C48: 4 | D48: 25 | E48: =C48*D48
B49: Natural Sponges (pack of 6) | C49: 6 | D49: 14 | E49: =C49*D49
A50: VEHICLES
B51: Used Cargo Van (2020-2022) | C51: 1 | D51: 22000 | E51: =C51*D51
B52: Vehicle Wrap/Branding | C52: 1 | D52: 2800 | E52: =C52*D52
...

Sheet Monthly Supply Costs
A1: HAVANA CLEANING — MONTHLY SUPPLY COSTS
A3: ITEM | B3: COST/UNIT | C3: UNITS/MONTH | D3: MONTHLY COST | E3: ANNUAL COST
A4: All-Purpose Cleaner (concentrate) | B4: 18 | C4: 4 | D4: =B4*C4 | E4: =D4*12
A5: Glass Cleaner (concentrate) | B5: 15 | C5: 3 | D5: =B5*C5 | E5: =D5*12
A6: Disinfectant Spray (concentrate) | B6: 22 | C6: 3 | D6: =B6*C6 | E6: =D6*12
A7: Toilet Bowl Cleaner | B7: 5.75 | C7: 8 | D7: =B7*C7 | E7: =D7*12
A8: Stainless Steel Cleaner | B8: 9 | C8: 3 | D8: =B8*C8 | E8: =D8*12
A9: Wood Floor Cleaner | B9: 14 | C9: 2 | D9: =B9*C9 | E9: =D9*12
A10: Tile & Grout Cleaner | B10: 16 | C10: 2 | D10: =B10*C10 | E10: =D10*12
A11: Degreaser (kitchen) | B11: 18 | C11: 2 | D11: =B11*C11 | E11: =D11*12
A12: Microfiber Cloths (24-pack) | B12: 22 | C12: 3 | D12: =B12*C12 | E12: =D12*12
A13: Sponges (12-pack) | B13: 8 | C13: 3 | D13: =B13*C13 | E13: =D13*12
A14: Magic Eraser Pads (10-pack) | B14: 12 | C14: 3 | D14: =B14*C14 | E14: =D14*12
A15: Trash Bags 13-gal (100ct) | B15: 18 | C15: 2 | D15: =B15*C15 | E15: =D15*12
... A25: Eco Disinfectant | B25: 28 | C25: 1 | D25: =B25*C25 | E25: =D25*12
A27: TOTAL MONTHLY SUPPLY COST | D27: =SUM(D4:D25) | E27: =SUM(E4:E25)

Sheet Employee Projections
A1: HAVANA CLEANING — YEAR 1 EMPLOYEE & LABOR COST MODEL
A2: Edit monthly headcounts (yellow). Wages auto-calculate from Inputs sheet rates.
A4: MONTHLY HEADCOUNT (editable)
A6: ROLE | B6: RATE SOURCE | C6: M1 | D6: M2 | E6: M3 | F6: M4 | G6: M5 | H6: M6 | I6: M7 | J6: M8 | K6: M9 | L6: M10 | M6: M11 | N6: M12
A7: Owner/Operator (cleaning + admin) | B7: Inputs B26 | C7: 1 | D7: 1 | E7: 1 | F7: 1 | G7: 1 | H7: 1 | I7: 1 | J7: 1 | K7: 1 | L7: 1 | M7: 1 | N7: 1
A8: Entry-Level Cleaners | B8: Inputs B17 | C8: 1 | D8: 1 | E8: 1 | F8: 2 | G8: 2 | H8: 2 | I8: 3 | J8: 3 | K8: 3 | L8: 3 | M8: 4 | N8: 4
A9: Senior Cleaners | B9: Inputs B18 | C9: 0 | D9: 0 | E9: 0 | F9: 0 | G9: 0 | H9: 1 | I9: 1 | J9: 1 | K9: 1 | L9: 1 | M9: 1 | N9: 1
A10: Part-Time Admin/Scheduler | B10: Inputs B20 | C10: 0 | D10: 0 | E10: 0 | F10: 0 | G10: 1 | H10: 1 | I10: 1 | J10: 1 | K10: 1 | L10: 1 | M10: 1 | N10: 1
A11: TOTAL HEADCOUNT | C11: =SUM(C7:C10) | D11: =SUM(D7:D10) | E11: =SUM(E7:E10) | F11: =SUM(F7:F10) | G11: =SUM(G7:G10) | H11: =SUM(H7:H10) | I11: =SUM(I7:I10) | J11: =SUM(J7:J10) | ... N11: =SUM(N7:N10)
A13: MONTHLY LABOR COST BREAKDOWN (auto-calculated)
A15: COST COMPONENT | C15: M1 | D15: M2 | E15: M3 | F15: M4 | G15: M5 | H15: M6 | I15: M7 | J15: M8 | K15: M9 | L15: M10 | M15: M11 | N15: M12 | O15: ANNUAL
A16: Entry-Level Cleaner Wages | C16: =C8*'Inputs'!$B$17*'Inputs'!$B$22 | D16: =D8*'Inputs'!$B$17*'Inputs'!$B$22 | E16: =E8*'Inputs'!$B$17*'Inputs'!$B$22 | F16: =F8*'Inputs'!$B$17*'Inputs'!$B$22 | G16: =G8*'Inputs'!$B$17*'Inputs'!$B$22 | H16: =H8*'Inputs'!$B$17*'Inputs'!$B$22 | I16: =I8*'Inputs'!$B$17*'Inputs'!$B$22 | J16: =J8*'Inputs'!$B$17*'Inputs'!$B$22 | ... N16: =N8*'Inputs'!$B$17*'Inputs'!$B$22 | O16: =SUM(C16:N16)
A17: Senior Cleaner Wages | C17: =C9*'Inputs'!$B$18*'Inputs'!$B$22 | D17: =D9*'Inputs'!$B$18*'Inputs'!$B$22 | E17: =E9*'Inputs'!$B$18*'Inputs'!$B$22 | F17: =F9*'Inputs'!$B$18*'Inputs'!$B$22 | G17: =G9*'Inputs'!$B$18*'Inputs'!$B$22 | H17: =H9*'Inputs'!$B$18*'Inputs'!$B$22 | I17: =I9*'Inputs'!$B$18*'Inputs'!$B$22 | J17: =J9*'Inputs'!$B$18*'Inputs'!$B$22 | ... N17: =N9*'Inputs'!$B$18*'Inputs'!$B$22 | O17: =SUM(C17:N17)
A18: Part-Time Admin Wages | C18: =C10*'Inputs'!$B$20*'Inputs'!$B$23 | D18: =D10*'Inputs'!$B$20*'Inputs'!$B$23 | E18: =E10*'Inputs'!$B$20*'Inputs'!$B$23 | F18: =F10*'Inputs'!$B$20*'Inputs'!$B$23 | G18: =G10*'Inputs'!$B$20*'Inputs'!$B$23 | H18: =H10*'Inputs'!$B$20*'Inputs'!$B$23 | I18: =I10*'Inputs'!$B$20*'Inputs'!$B$23 | J18: =J10*'Inputs'!$B$20*'Inputs'!$B$23 | ... N18: =N10*'Inputs'!$B$20*'Inputs'!$B$23 | O18: =SUM(C18:N18)
A19: GROSS WAGES SUBTOTAL | C19: =C16+C17+C18 | D19: =D16+D17+D18 | E19: =E16+E17+E18 | F19: =F16+F17+F18 | G19: =G16+G17+G18 | H19: =H16+H17+H18 | I19: =I16+I17+I18 | J19: =J16+J17+J18 | ... N19: =N16+N17+N18 | O19: =SUM(C19:N19)
A20: Payroll Taxes (FICA) | C20: =C19*'Inputs'!$B$31 | D20: =D19*'Inputs'!$B$31 | E20: =E19*'Inputs'!$B$31 | F20: =F19*'Inputs'!$B$31 | G20: =G19*'Inputs'!$B$31 | H20: =H19*'Inputs'!$B$31 | I20: =I19*'Inputs'!$B$31 | J20: =J19*'Inputs'!$B$31 | ... N20: =N19*'Inputs'!$B$31 | O20: =SUM(C20:N20)
A21: Workers Compensation | C21: =C19*'Inputs'!$B$32 | D21: =D19*'Inputs'!$B$32 | E21: =E19*'Inputs'!$B$32 | F21: =F19*'Inputs'!$B$32 | G21: =G19*'Inputs'!$B$32 | H21: =H19*'Inputs'!$B$32 | I21: =I19*'Inputs'!$B$32 | J21: =J19*'Inputs'!$B$32 | ... N21: =N19*'Inputs'!$B$32 | O21: =SUM(C21:N21)
A22: Employee Benefits | B22: FT employees only | C22: =(C8+C9)*'Inputs'!$B$33 | D22: =(D8+D9)*'Inputs'!$B$33 | E22: =(E8+E9)*'Inputs'!$B$33 | F22: =(F8+F9)*'Inputs'!$B$33 | G22: =(G8+G9)*'Inputs'!$B$33 | H22: =(H8+H9)*'Inputs'!$B$33 | I22: =(I8+I9)*'Inputs'!$B$33 | J22: =(J8+J9)*'Inputs'!$B$33 | ... N22: =(N8+N9)*'Inputs'!$B$33 | O22: =SUM(C22:N22)
A23: TOTAL LABOR COST (All-In) | C23: =C19+C20+C21+C22 | D23: =D19+D20+D21+D22 | E23: =E19+E20+E21+E22 | F23: =F19+F20+F21+F22 | G23: =G19+G20+G21+G22 | H23: =H19+H20+H21+H22 | I23: =I19+I20+I21+I22 | J23: =J19+J20+J21+J22 | ... N23: =N19+N20+N21+N22 | O23: =SUM(C23:N23)

Sheet Revenue Projections
A1: HAVANA CLEANING — REVENUE PROJECTIONS (YEAR 1)
A2: Edit monthly job counts (yellow). Prices pull from Inputs sheet.
A4: MONTHLY JOB COUNTS (editable)
A6: SERVICE TYPE | B6: PRICE SOURCE | C6: M1 | D6: M2 | E6: M3 | F6: M4 | G6: M5 | H6: M6 | I6: M7 | J6: M8 | K6: M9 | L6: M10 | M6: M11 | N6: M12 | O6: ANNUAL JOBS
A7: Residential Cleaning | B7: Inputs B5 | C7: 8 | D7: 10 | E7: 14 | F7: 18 | G7: 22 | H7: 25 | I7: 28 | J7: 30 | K7: 33 | L7: 36 | M7: 40 | N7: 45 | O7: =SUM(C7:N7)
A8: Deep Clean | B8: Inputs B6 | C8: 2 | D8: 3 | E8: 4 | F8: 5 | G8: 6 | H8: 7 | I8: 8 | J8: 8 | K8: 9 | L8: 10 | M8: 11 | N8: 12 | O8: =SUM(C8:N8)
A9: Move-In/Move-Out | B9: Inputs B7 | C9: 1 | D9: 1 | E9: 2 | F9: 2 | G9: 3 | H9: 3 | I9: 4 | J9: 4 | K9: 5 | L9: 5 | M9: 6 | N9: 6 | O9: =SUM(C9:N9)
A10: Post-Construction | B10: Inputs B8 | C10: 0 | D10: 1 | E10: 1 | F10: 1 | G10: 2 | H10: 2 | I10: 2 | J10: 3 | K10: 3 | L10: 3 | M10: 4 | N10: 4 | O10: =SUM(C10:N10)
A11: Airbnb Turnover | B11: Inputs B9 | C11: 2 | D11: 3 | E11: 4 | F11: 5 | G11: 6 | H11: 8 | I11: 10 | J11: 12 | K11: 10 | L11: 8 | M11: 6 | N11: 8 | O11: =SUM(C11:N11)
A12: Green Clean | B12: Inputs B10 | C12: 1 | D12: 1 | E12: 2 | F12: 2 | G12: 3 | H12: 3 | I12: 4 | J12: 4 | K12: 5 | L12: 5 | M12: 6 | N12: 6 | O12: =SUM(C12:N12)
A13: Recurring Plans | B13: Inputs B11 | C13: 3 | D13: 5 | E13: 8 | F13: 12 | G13: 16 | H13: 20 | I13: 24 | J13: 28 | K13: 32 | L13: 36 | M13: 40 | N13: 44 | O13: =SUM(C13:N13)
A14: Commercial (Monthly) | B14: Inputs B12 | C14: 0 | D14: 0 | E14: 0 | F14: 1 | G14: 1 | H14: 1 | I14: 2 | J14: 2 | K14: 2 | L14: 3 | M14: 3 | N14: 3 | O14: =SUM(C14:N14)
A15: TOTAL JOBS | C15: =SUM(C7:C14) | D15: =SUM(D7:D14) | E15: =SUM(E7:E14) | F15: =SUM(F7:F14) | G15: =SUM(G7:G14) | H15: =SUM(H7:H14) | I15: =SUM(I7:I14) | J15: =SUM(J7:J14) | ... N15: =SUM(N7:N14) | O15: =SUM(C15:N15)
A17: MONTHLY REVENUE BY SERVICE (auto-calculated: jobs x price)
A19: SERVICE TYPE | B19: UNIT PRICE | C19: M1 | D19: M2 | E19: M3 | F19: M4 | G19: M5 | H19: M6 | I19: M7 | J19: M8 | K19: M9 | L19: M10 | M19: M11 | N19: M12 | O19: ANNUAL REV
A20: Residential Cleaning | B20: ='Inputs'!$B$5 | C20: =C7*'Inputs'!$B$5 | D20: =D7*'Inputs'!$B$5 | E20: =E7*'Inputs'!$B$5 | F20: =F7*'Inputs'!$B$5 | G20: =G7*'Inputs'!$B$5 | H20: =H7*'Inputs'!$B$5 | I20: =I7*'Inputs'!$B$5 | J20: =J7*'Inputs'!$B$5 | ... N20: =N7*'Inputs'!$B$5 | O20: =SUM(C20:N20)
A21: Deep Clean | B21: ='Inputs'!$B$6 | C21: =C8*'Inputs'!$B$6 | D21: =D8*'Inputs'!$B$6 | E21: =E8*'Inputs'!$B$6 | F21: =F8*'Inputs'!$B$6 | G21: =G8*'Inputs'!$B$6 | H21: =H8*'Inputs'!$B$6 | I21: =I8*'Inputs'!$B$6 | J21: =J8*'Inputs'!$B$6 | ... N21: =N8*'Inputs'!$B$6 | O21: =SUM(C21:N21)
A22: Move-In/Move-Out | B22: ='Inputs'!$B$7 | C22: =C9*'Inputs'!$B$7 | D22: =D9*'Inputs'!$B$7 | E22: =E9*'Inputs'!$B$7 | F22: =F9*'Inputs'!$B$7 | G22: =G9*'Inputs'!$B$7 | H22: =H9*'Inputs'!$B$7 | I22: =I9*'Inputs'!$B$7 | J22: =J9*'Inputs'!$B$7 | ... N22: =N9*'Inputs'!$B$7 | O22: =SUM(C22:N22)
A23: Post-Construction | B23: ='Inputs'!$B$8 | C23: =C10*'Inputs'!$B$8 | D23: =D10*'Inputs'!$B$8 | E23: =E10*'Inputs'!$B$8 | F23: =F10*'Inputs'!$B$8 | G23: =G10*'Inputs'!$B$8 | H23: =H10*'Inputs'!$B$8 | I23: =I10*'Inputs'!$B$8 | J23: =J10*'Inputs'!$B$8 | ... N23: =N10*'Inputs'!$B$8 | O23: =SUM(C23:N23)
A24: Airbnb Turnover | B24: ='Inputs'!$B$9 | C24: =C11*'Inputs'!$B$9 | D24: =D11*'Inputs'!$B$9 | E24: =E11*'Inputs'!$B$9 | F24: =F11*'Inputs'!$B$9 | G24: =G11*'Inputs'!$B$9 | H24: =H11*'Inputs'!$B$9 | I24: =I11*'Inputs'!$B$9 | J24: =J11*'Inputs'!$B$9 | ... N24: =N11*'Inputs'!$B$9 | O24: =SUM(C24:N24)
A25: Green Clean | B25: ='Inputs'!$B$10 | C25: =C12*'Inputs'!$B$10 | D25: =D12*'Inputs'!$B$10 | E25: =E12*'Inputs'!$B$10 | F25: =F12*'Inputs'!$B$10 | G25: =G12*'Inputs'!$B$10 | H25: =H12*'Inputs'!$B$10 | I25: =I12*'Inputs'!$B$10 | J25: =J12*'Inputs'!$B$10 | ... N25: =N12*'Inputs'!$B$10 | O25: =SUM(C25:N25)
A26: Recurring Plans | B26: ='Inputs'!$B$11 | C26: =C13*'Inputs'!$B$11 | D26: =D13*'Inputs'!$B$11 | E26: =E13*'Inputs'!$B$11 | F26: =F13*'Inputs'!$B$11 | G26: =G13*'Inputs'!$B$11 | H26: =H13*'Inputs'!$B$11 | I26: =I13*'Inputs'!$B$11 | J26: =J13*'Inputs'!$B$11 | ... N26: =N13*'Inputs'!$B$11 | O26: =SUM(C26:N26)
A27: Commercial (Monthly) | B27: ='Inputs'!$B$12 | C27: =C14*'Inputs'!$B$12 | D27: =D14*'Inputs'!$B$12 | E27: =E14*'Inputs'!$B$12 | F27: =F14*'Inputs'!$B$12 | G27: =G14*'Inputs'!$B$12 | H27: =H14*'Inputs'!$B$12 | I27: =I14*'Inputs'!$B$12 | J27: =J14*'Inputs'!$B$12 | ... N27: =N14*'Inputs'!$B$12 | O27: =SUM(C27:N27)
A28: Add-On Services Revenue | B28: ='Inputs'!$B$13 | C28: =(C15-C14)*'Inputs'!$B$13*'Inputs'!$B$14 | D28: =(D15-D14)*'Inputs'!$B$13*'Inputs'!$B$14 | E28: =(E15-E14)*'Inputs'!$B$13*'Inputs'!$B$14 | F28: =(F15-F14)*'Inputs'!$B$13*'Inputs'!$B$14 | G28: =(G15-G14)*'Inputs'!$B$13*'Inputs'!$B$14 | H28: =(H15-H14)*'Inputs'!$B$13*'Inputs'!$B$14 | I28: =(I15-I14)*'Inputs'!$B$13*'Inputs'!$B$14 | J28: =(J15-J14)*'Inputs'!$B$13*'Inputs'!$B$14 | ... N28: =(N15-N14)*'Inputs'!$B$13*'Inputs'!$B$14 | O28: =SUM(C28:N28)
A29: TOTAL GROSS REVENUE | C29: =SUM(C20:C28) | D29: =SUM(D20:D28) | E29: =SUM(E20:E28) | F29: =SUM(F20:F28) | G29: =SUM(G20:G28) | H29: =SUM(H20:H28) | I29: =SUM(I20:I28) | J29: =SUM(J20:J28) | ... N29: =SUM(N20:N28) | O29: =SUM(C29:N29)

Sheet Operating Expenses
A1: HAVANA CLEANING — MONTHLY OPERATING EXPENSES (YEAR 1)
A2: Edit monthly amounts (yellow). Category totals and grand total auto-calculate.
A4: EXPENSE CATEGORY | B4: DETAIL | C4: M1 | D4: M2 | E4: M3 | F4: M4 | G4: M5 | H4: M6 | I4: M7 | J4: M8 | K4: M9 | L4: M10 | M4: M11 | N4: M12 | O4: ANNUAL
A5: VEHICLE EXPENSES
B6: Gas (per vehicle) | C6: ='Inputs'!$B$36*'Inputs'!$B$25 | D6: ='Inputs'!$B$36*'Inputs'!$B$25 | E6: ='Inputs'!$B$36*'Inputs'!$B$25 | F6: ='Inputs'!$B$36*'Inputs'!$B$25 | G6: ='Inputs'!$B$36*'Inputs'!$B$25 | H6: ='Inputs'!$B$36*'Inputs'!$B$25 | I6: ='Inputs'!$B$36*'Inputs'!$B$25 | J6: ='Inputs'!$B$36*'Inputs'!$B$25 | ... N6: ='Inputs'!$B$36*'Inputs'!$B$25 | O6: =SUM(C6:N6)
B7: Vehicle Insurance (per vehicle) | C7: ='Inputs'!$B$37 | D7: ='Inputs'!$B$37 | E7: ='Inputs'!$B$37 | F7: ='Inputs'!$B$37 | G7: ='Inputs'!$B$37 | H7: ='Inputs'!$B$37 | I7: ='Inputs'!$B$37 | J7: ='Inputs'!$B$37 | ... N7: ='Inputs'!$B$37 | O7: =SUM(C7:N7)
B8: Vehicle Maintenance | C8: ='Inputs'!$B$38 | D8: ='Inputs'!$B$38 | E8: ='Inputs'!$B$38 | F8: ='Inputs'!$B$38 | G8: ='Inputs'!$B$38 | H8: ='Inputs'!$B$38 | I8: ='Inputs'!$B$38 | J8: ='Inputs'!$B$38 | ... N8: ='Inputs'!$B$38 | O8: =SUM(C8:N8)
B9: Parking & Tolls | C9: ='Inputs'!$B$39 | D9: ='Inputs'!$B$39 | E9: ='Inputs'!$B$39 | F9: ='Inputs'!$B$39 | G9: ='Inputs'!$B$39 | H9: ='Inputs'!$B$39 | I9: ='Inputs'!$B$39 | J9: ='Inputs'!$B$39 | ... N9: ='Inputs'!$B$39 | O9: =SUM(C9:N9)
B10: VEHICLE EXPENSES SUBTOTAL | C10: =SUM(C6:C9) | D10: =SUM(D6:D9) | E10: =SUM(E6:E9) | F10: =SUM(F6:F9) | G10: =SUM(G6:G9) | H10: =SUM(H6:H9) | I10: =SUM(I6:I9) | J10: =SUM(J6:J9) | ... N10: =SUM(N6:N9) | O10: =SUM(C10:N10)
A11: INSURANCE & LICENSES
B12: General Liability Insurance | C12: ='Inputs'!$B$48 | D12: ='Inputs'!$B$48 | E12: ='Inputs'!$B$48 | F12: ='Inputs'!$B$48 | G12: ='Inputs'!$B$48 | H12: ='Inputs'!$B$48 | I12: ='Inputs'!$B$48 | J12: ='Inputs'!$B$48 | ... N12: ='Inputs'!$B$48 | O12: =SUM(C12:N12)
B13: Workers Compensation Insurance | C13: ='Inputs'!$B$49 | D13: ='Inputs'!$B$49 | E13: ='Inputs'!$B$49 | F13: ='Inputs'!$B$49 | G13: ='Inputs'!$B$49 | H13: ='Inputs'!$B$49 | I13: ='Inputs'!$B$49 | J13: ='Inputs'!$B$49 | ... N13: ='Inputs'!$B$49 | O13: =SUM(C13:N13)
B14: Surety Bond | C14: ='Inputs'!$B$50 | D14: ='Inputs'!$B$50 | E14: ='Inputs'!$B$50 | F14: ='Inputs'!$B$50 | G14: ='Inputs'!$B$50 | H14: ='Inputs'!$B$50 | I14: ='Inputs'!$B$50 | J14: ='Inputs'!$B$50 | ... N14: ='Inputs'!$B$50 | O14: =SUM(C14:N14)
B15: INSURANCE & LICENSES SUBTOTAL | C15: =SUM(C12:C14) | D15: =SUM(D12:D14) | E15: =SUM(E12:E14) | F15: =SUM(F12:F14) | G15: =SUM(G12:G14) | H15: =SUM(H12:H14) | I15: =SUM(I12:I14) | J15: =SUM(J12:J14) | ... N15: =SUM(N12:N14) | O15: =SUM(C15:N15)
A16: MARKETING & ADVERTISING
B17: Google Ads (PPC) | C17: 800 | D17: 800 | E17: 900 | F17: 900 | G17: 1000 | H17: 1000 | I17: 1200 | J17: 1200 | K17: 1000 | L17: 1000 | M17: 1200 | N17: 1500 | O17: =SUM(C17:N17)
B18: Facebook/Instagram Ads | C18: 500 | D18: 500 | E18: 600 | F18: 600 | G18: 700 | H18: 700 | I18: 800 | J18: 800 | K18: 700 | L18: 700 | M18: 800 | N18: 1000 | O18: =SUM(C18:N18)
B19: Yelp Advertising | C19: 200 | D19: 200 | E19: 200 | F19: 200 | G19: 200 | H19: 200 | I19: 300 | J19: 300 | K19: 300 | L19: 300 | M19: 300 | N19: 300 | O19: =SUM(C19:N19)
B20: Nextdoor / Local Ads | C20: 100 | D20: 100 | E20: 100 | F20: 100 | G20: 100 | H20: 100 | I20: 150 | J20: 150 | K20: 150 | L20: 150 | M20: 150 | N20: 150 | O20: =SUM(C20:N20)
B21: Referral Program Costs | C21: 0 | D21: 25 | E21: 50 | F21: 75 | G21: 100 | H21: 125 | I21: 150 | J21: 175 | K21: 200 | L21: 225 | M21: 250 | N21: 275 | O21: =SUM(C21:N21)
B22: Printed Materials | C22: 100 | D22: 50 | E22: 50 | F22: 50 | G22: 100 | H22: 50 | I22: 50 | J22: 50 | K22: 100 | L22: 50 | M22: 50 | N22: 100 | O22: =SUM(C22:N22)
B23: MARKETING & ADVERTISING SUBTOTAL | C23: =SUM(C17:C22) | D23: =SUM(D17:D22) | E23: =SUM(E17:E22) | F23: =SUM(F17:F22) | G23: =SUM(G17:G22) | H23: =SUM(H17:H22) | I23: =SUM(I17:I22) | J23: =SUM(J17:J22) | ... N23: =SUM(N17:N22) | O23: =SUM(C23:N23)
A24: TECHNOLOGY & SOFTWARE
B25: Website Hosting | C25: ='Inputs'!$B$53 | D25: ='Inputs'!$B$53 | E25: ='Inputs'!$B$53 | F25: ='Inputs'!$B$53 | G25: ='Inputs'!$B$53 | H25: ='Inputs'!$B$53 | I25: ='Inputs'!$B$53 | J25: ='Inputs'!$B$53 | ... N25: ='Inputs'!$B$53 | O25: =SUM(C25:N25)
B26: Scheduling/CRM | C26: ='Inputs'!$B$54 | D26: ='Inputs'!$B$54 | E26: ='Inputs'!$B$54 | F26: ='Inputs'!$B$54 | G26: ='Inputs'!$B$54 | H26: ='Inputs'!$B$54 | I26: ='Inputs'!$B$54 | J26: ='Inputs'!$B$54 | ... N26: ='Inputs'!$B$54 | O26: =SUM(C26:N26)
B27: QuickBooks | C27: ='Inputs'!$B$55 | D27: ='Inputs'!$B$55 | E27: ='Inputs'!$B$55 | F27: ='Inputs'!$B$55 | G27: ='Inputs'!$B$55 | H27: ='Inputs'!$B$55 | I27: ='Inputs'!$B$55 | J27: ='Inputs'!$B$55 | ... N27: ='Inputs'!$B$55 | O27: =SUM(C27:N27)
B28: Business Phone | C28: ='Inputs'!$B$56 | D28: ='Inputs'!$B$56 | E28: ='Inputs'!$B$56 | F28: ='Inputs'!$B$56 | G28: ='Inputs'!$B$56 | H28: ='Inputs'!$B$56 | I28: ='Inputs'!$B$56 | J28: ='Inputs'!$B$56 | ... N28: ='Inputs'!$B$56 | O28: =SUM(C28:N28)
B29: Stripe Processing Fees | C29: ='Revenue Projections'!C29*'Inputs'!$B$59+'Revenue Projections'!C15*'Inputs'!$B$60 | D29: ='Revenue Projections'!D29*'Inputs'!$B$59+'Revenue Projections'!D15*'Inputs'!$B$60 | E29: ='Revenue Projections'!E29*'Inputs'!$B$59+'Revenue Projections'!E15*'Inputs'!$B$60 | F29: ='Revenue Projections'!F29*'Inputs'!$B$59+'Revenue Projections'!F15*'Inputs'!$B$60 | G29: ='Revenue Projections'!G29*'Inputs'!$B$59+'Revenue Projections'!G15*'Inputs'!$B$60 | H29: ='Revenue Projections'!H29*'Inputs'!$B$59+'Revenue Projections'!H15*'Inputs'!$B$60 | I29: ='Revenue Projections'!I29*'Inputs'!$B$59+'Revenue Projections'!I15*'Inputs'!$B$60 | J29: ='Revenue Projections'!J29*'Inputs'!$B$59+'Revenue Projections'!J15*'Inputs'!$B$60 | ... N29: ='Revenue Projections'!N29*'Inputs'!$B$59+'Revenue Projections'!N15*'Inputs'!$B$60 | O29: =SUM(C29:N29)
B30: Internet | C30: ='Inputs'!$B$57 | D30: ='Inputs'!$B$57 | E30: ='Inputs'!$B$57 | F30: ='Inputs'!$B$57 | G30: ='Inputs'!$B$57 | H30: ='Inputs'!$B$57 | I30: ='Inputs'!$B$57 | J30: ='Inputs'!$B$57 | ... N30: ='Inputs'!$B$57 | O30: =SUM(C30:N30)
B31: Cell Phone Plans | C31: ='Inputs'!$B$58 | D31: ='Inputs'!$B$58 | E31: ='Inputs'!$B$58 | F31: ='Inputs'!$B$58 | G31: ='Inputs'!$B$58 | H31: ='Inputs'!$B$58 | I31: ='Inputs'!$B$58 | J31: ='Inputs'!$B$58 | ... N31: ='Inputs'!$B$58 | O31: =SUM(C31:N31)
B32: TECHNOLOGY & SOFTWARE SUBTOTAL | C32: =SUM(C25:C31) | D32: =SUM(D25:D31) | E32: =SUM(E25:E31) | F32: =SUM(F25:F31) | G32: =SUM(G25:G31) | H32: =SUM(H25:H31) | I32: =SUM(I25:I31) | J32: =SUM(J25:J31) | ... N32: =SUM(N25:N31) | O32: =SUM(C32:N32)
A33: CLEANING SUPPLIES
B34: Monthly Supply Costs | C34: ='Monthly Supply Costs'!D27 | D34: ='Monthly Supply Costs'!D27 | E34: ='Monthly Supply Costs'!D27 | F34: ='Monthly Supply Costs'!D27 | G34: ='Monthly Supply Costs'!D27 | H34: ='Monthly Supply Costs'!D27 | I34: ='Monthly Supply Costs'!D27 | J34: ='Monthly Supply Costs'!D27 | K34: ='Monthly Supply Costs'!D27 | L34: ='Monthly Supply Costs'!D27 | M34: ='Monthly Supply Costs'!D27 | N34: ='Monthly Supply Costs'!D27 | O34: =SUM(C34:N34)
B35: Equipment Repair/Replace | C35: 75 | D35: 75 | E35: 75 | F35: 100 | G35: 100 | H35: 100 | I35: 125 | J35: 125 | K35: 125 | L35: 150 | M35: 150 | N35: 150 | O35: =SUM(C35:N35)
B36: CLEANING SUPPLIES SUBTOTAL | C36: =SUM(C34:C35) | D36: =SUM(D34:D35) | E36: =SUM(E34:E35) | F36: =SUM(F34:F35) | G36: =SUM(G34:G35) | H36: =SUM(H34:H35) | I36: =SUM(I34:I35) | J36: =SUM(J34:J35) | ... N36: =SUM(N34:N35) | O36: =SUM(C36:N36)
A37: OFFICE & ADMIN
B38: Office Supplies | C38: ='Inputs'!$B$63 | D38: ='Inputs'!$B$63 | E38: ='Inputs'!$B$63 | F38: ='Inputs'!$B$63 | G38: ='Inputs'!$B$63 | H38: ='Inputs'!$B$63 | I38: ='Inputs'!$B$63 | J38: ='Inputs'!$B$63 | ... N38: ='Inputs'!$B$63 | O38: =SUM(C38:N38)
B39: Storage Unit | C39: ='Inputs'!$B$64 | D39: ='Inputs'!$B$64 | E39: ='Inputs'!$B$64 | F39: ='Inputs'!$B$64 | G39: ='Inputs'!$B$64 | H39: ='Inputs'!$B$64 | I39: ='Inputs'!$B$64 | J39: ='Inputs'!$B$64 | ... N39: ='Inputs'!$B$64 | O39: =SUM(C39:N39)
B40: Accounting Service | C40: ='Inputs'!$B$65 | D40: ='Inputs'!$B$65 | E40: ='Inputs'!$B$65 | F40: ='Inputs'!$B$65 | G40: ='Inputs'!$B$65 | H40: ='Inputs'!$B$65 | I40: ='Inputs'!$B$65 | J40: ='Inputs'!$B$65 | ... N40: ='Inputs'!$B$65 | O40: =SUM(C40:N40)
B41: Postage | C41: ='Inputs'!$B$66 | D41: ='Inputs'!$B$66 | E41: ='Inputs'!$B$66 | F41: ='Inputs'!$B$66 | G41: ='Inputs'!$B$66 | H41: ='Inputs'!$B$66 | I41: ='Inputs'!$B$66 | J41: ='Inputs'!$B$66 | ... N41: ='Inputs'!$B$66 | O41: =SUM(C41:N41)
...

Sheet Profit & Loss
A1: HAVANA CLEANING — PROFIT & LOSS STATEMENT (YEAR 1)
A2: All values auto-calculate from Revenue, Employee, and OpEx sheets.
A4: LINE ITEM | C4: M1 | D4: M2 | E4: M3 | F4: M4 | G4: M5 | H4: M6 | I4: M7 | J4: M8 | K4: M9 | L4: M10 | M4: M11 | N4: M12 | O4: ANNUAL
A5: REVENUE
A6: Total Revenue | C6: ='Revenue Projections'!C29 | D6: ='Revenue Projections'!D29 | E6: ='Revenue Projections'!E29 | F6: ='Revenue Projections'!F29 | G6: ='Revenue Projections'!G29 | H6: ='Revenue Projections'!H29 | I6: ='Revenue Projections'!I29 | J6: ='Revenue Projections'!J29 | ... N6: ='Revenue Projections'!N29 | O6: =SUM(C6:N6)
A8: COST OF GOODS SOLD (Direct Costs)
A9: Direct Labor (all-in) | B9: From Employee Projections | C9: ='Employee Projections'!C23 | D9: ='Employee Projections'!D23 | E9: ='Employee Projections'!E23 | F9: ='Employee Projections'!F23 | G9: ='Employee Projections'!G23 | H9: ='Employee Projections'!H23 | I9: ='Employee Projections'!I23 | J9: ='Employee Projections'!J23 | ... N9: ='Employee Projections'!N23 | O9: =SUM(C9:N9)
A10: Cleaning Supplies | C10: ='Monthly Supply Costs'!D27 | D10: ='Monthly Supply Costs'!D27 | E10: ='Monthly Supply Costs'!D27 | F10: ='Monthly Supply Costs'!D27 | G10: ='Monthly Supply Costs'!D27 | H10: ='Monthly Supply Costs'!D27 | I10: ='Monthly Supply Costs'!D27 | J10: ='Monthly Supply Costs'!D27 | K10: ='Monthly Supply Costs'!D27 | L10: ='Monthly Supply Costs'!D27 | M10: ='Monthly Supply Costs'!D27 | N10: ='Monthly Supply Costs'!D27 | O10: =SUM(C10:N10)
A11: Vehicle Fuel | C11: ='Inputs'!$B$36*'Inputs'!$B$25 | D11: ='Inputs'!$B$36*'Inputs'!$B$25 | E11: ='Inputs'!$B$36*'Inputs'!$B$25 | F11: ='Inputs'!$B$36*'Inputs'!$B$25 | G11: ='Inputs'!$B$36*'Inputs'!$B$25 | H11: ='Inputs'!$B$36*'Inputs'!$B$25 | I11: ='Inputs'!$B$36*'Inputs'!$B$25 | J11: ='Inputs'!$B$36*'Inputs'!$B$25 | ... N11: ='Inputs'!$B$36*'Inputs'!$B$25 | O11: =SUM(C11:N11)
A12: TOTAL COGS | C12: =C9+C10+C11 | D12: =D9+D10+D11 | E12: =E9+E10+E11 | F12: =F9+F10+F11 | G12: =G9+G10+G11 | H12: =H9+H10+H11 | I12: =I9+I10+I11 | J12: =J9+J10+J11 | ... N12: =N9+N10+N11 | O12: =SUM(C12:N12)
A13: GROSS PROFIT | C13: =C6-C12 | D13: =D6-D12 | E13: =E6-E12 | F13: =F6-F12 | G13: =G6-G12 | H13: =H6-H12 | I13: =I6-I12 | J13: =J6-J12 | ... N13: =N6-N12 | O13: =SUM(C13:N13)
A14: Gross Margin % | C14: =IF(C6=0,0,C13/C6) | D14: =IF(D6=0,0,D13/D6) | E14: =IF(E6=0,0,E13/E6) | F14: =IF(F6=0,0,F13/F6) | G14: =IF(G6=0,0,G13/G6) | H14: =IF(H6=0,0,H13/H6) | I14: =IF(I6=0,0,I13/I6) | J14: =IF(J6=0,0,J13/J6) | ... O14: =IF(O6=0,0,O13/O6)
A16: OPERATING EXPENSES (SG&A)
A17: Total Operating Expenses | B17: From OpEx sheet | C17: ='Operating Expenses'!C54 | D17: ='Operating Expenses'!D54 | E17: ='Operating Expenses'!E54 | F17: ='Operating Expenses'!F54 | G17: ='Operating Expenses'!G54 | H17: ='Operating Expenses'!H54 | I17: ='Operating Expenses'!I54 | J17: ='Operating Expenses'!J54 | ... N17: ='Operating Expenses'!N54 | O17: =SUM(C17:N17)
A19: NET OPERATING INCOME | C19: =C13-C17 | D19: =D13-D17 | E19: =E13-E17 | F19: =F13-F17 | G19: =G13-G17 | H19: =H13-H17 | I19: =I13-I17 | J19: =J13-J17 | ... N19: =N13-N17 | O19: =SUM(C19:N19)
A20: Net Margin % | C20: =IF(C6=0,0,C19/C6) | D20: =IF(D6=0,0,D19/D6) | E20: =IF(E6=0,0,E19/E6) | F20: =IF(F6=0,0,F19/F6) | G20: =IF(G6=0,0,G19/G6) | H20: =IF(H6=0,0,H19/H6) | I20: =IF(I6=0,0,I19/I6) | J20: =IF(J6=0,0,J19/J6) | ... O20: =IF(O6=0,0,O19/O6)
A22: CUMULATIVE NET INCOME | C22: =C19 | D22: =C22+D19 | E22: =D22+E19 | F22: =E22+F19 | G22: =F22+G19 | H22: =G22+H19 | I22: =H22+I19 | J22: =I22+J19 | K22: =J22+K19 | ... N22: =M22+N19 | O22: =N22

Sheet Cash Flow
A1: HAVANA CLEANING — CASH FLOW PROJECTIONS (YEAR 1)
A3: CASH FLOW ITEM | C3: M1 | D3: M2 | E3: M3 | F3: M4 | G3: M5 | H3: M6 | I3: M7 | J3: M8 | K3: M9 | L3: M10 | M3: M11 | N3: M12 | O3: ANNUAL
A4: BEGINNING CASH BALANCE | C4: 0 | D4: =C17 | E4: =D17 | F4: =E17 | G4: =F17 | H4: =G17 | I4: =H17 | J4: =I17 | K4: =J17 | ... N4: =M17
A5: CASH INFLOWS
B6: Cash from Services | C6: ='Profit & Loss'!C6*'Inputs'!$B$71 | D6: ='Profit & Loss'!D6*'Inputs'!$B$71+'Profit & Loss'!C6*'Inputs'!$B$72 | E6: ='Profit & Loss'!E6*'Inputs'!$B$71+'Profit & Loss'!D6*'Inputs'!$B$72 | F6: ='Profit & Loss'!F6*'Inputs'!$B$71+'Profit & Loss'!E6*'Inputs'!$B$72 | G6: ='Profit & Loss'!G6*'Inputs'!$B$71+'Profit & Loss'!F6*'Inputs'!$B$72 | H6: ='Profit & Loss'!H6*'Inputs'!$B$71+'Profit & Loss'!G6*'Inputs'!$B$72 | I6: ='Profit & Loss'!I6*'Inputs'!$B$71+'Profit & Loss'!H6*'Inputs'!$B$72 | J6: ='Profit & Loss'!J6*'Inputs'!$B$71+'Profit & Loss'!I6*'Inputs'!$B$72 | K6: ='Profit & Loss'!K6*'Inputs'!$B$71+'Profit & Loss'!J6*'Inputs'!$B$72 | ... N6: ='Profit & Loss'!N6*'Inputs'!$B$71+'Profit & Loss'!M6*'Inputs'!$B$72 | O6: =SUM(C6:N6)
B7: Owner Capital Investment | C7: ='Startup Costs'!E100+5000 | D7: 0 | E7: 0 | F7: 0 | G7: 0 | H7: 0 | I7: 0 | J7: 0 | K7: 0 | L7: 0 | M7: 0 | N7: 0 | O7: =SUM(C7:N7)
A8: TOTAL CASH INFLOWS | C8: =C6+C7 | D8: =D6+D7 | E8: =E6+E7 | F8: =F6+F7 | G8: =G6+G7 | H8: =H6+H7 | I8: =I6+I7 | J8: =J6+J7 | ... N8: =N6+N7 | O8: =SUM(C8:N8)
A9: CASH OUTFLOWS
B10: Labor Costs (all-in) | C10: ='Profit & Loss'!C9 | D10: ='Profit & Loss'!D9 | E10: ='Profit & Loss'!E9 | F10: ='Profit & Loss'!F9 | G10: ='Profit & Loss'!G9 | H10: ='Profit & Loss'!H9 | I10: ='Profit & Loss'!I9 | J10: ='Profit & Loss'!J9 | ... N10: ='Profit & Loss'!N9 | O10: =SUM(C10:N10)
B11: Operating Expenses | C11: ='Operating Expenses'!C54 | D11: ='Operating Expenses'!D54 | E11: ='Operating Expenses'!E54 | F11: ='Operating Expenses'!F54 | G11: ='Operating Expenses'!G54 | H11: ='Operating Expenses'!H54 | I11: ='Operating Expenses'!I54 | J11: ='Operating Expenses'!J54 | ... N11: ='Operating Expenses'!N54 | O11: =SUM(C11:N11)
B12: Cleaning Supplies | C12: ='Monthly Supply Costs'!D27 | D12: ='Monthly Supply Costs'!D27 | E12: ='Monthly Supply Costs'!D27 | F12: ='Monthly Supply Costs'!D27 | G12: ='Monthly Supply Costs'!D27 | H12: ='Monthly Supply Costs'!D27 | I12: ='Monthly Supply Costs'!D27 | J12: ='Monthly Supply Costs'!D27 | K12: ='Monthly Supply Costs'!D27 | L12: ='Monthly Supply Costs'!D27 | M12: ='Monthly Supply Costs'!D27 | N12: ='Monthly Supply Costs'!D27 | O12: =SUM(C12:N12)
B13: Startup Costs (Month 1) | C13: ='Startup Costs'!E100 | D13: 0 | E13: 0 | F13: 0 | G13: 0 | H13: 0 | I13: 0 | J13: 0 | K13: 0 | L13: 0 | M13: 0 | N13: 0 | O13: =SUM(C13:N13)
B14: Sales Tax Remittance (quarterly) | C14: 0 | D14: 0 | E14: =('Profit & Loss'!C6+'Profit & Loss'!D6+'Profit & Loss'!E6)*'Inputs'!$B$45 | F14: 0 | G14: 0 | H14: =('Profit & Loss'!F6+'Profit & Loss'!G6+'Profit & Loss'!H6)*'Inputs'!$B$45 | I14: 0 | J14: 0 | K14: =('Profit & Loss'!I6+'Profit & Loss'!J6+'Profit & Loss'!K6)*'Inputs'!$B$45 | L14: 0 | M14: 0 | N14: =('Profit & Loss'!L6+'Profit & Loss'!M6+'Profit & Loss'!N6)*'Inputs'!$B$45 | O14: =SUM(C14:N14)
A15: TOTAL CASH OUTFLOWS | C15: =C10+C11+C12+C13+C14 | D15: =D10+D11+D12+D13+D14 | E15: =E10+E11+E12+E13+E14 | F15: =F10+F11+F12+F13+F14 | G15: =G10+G11+G12+G13+G14 | H15: =H10+H11+H12+H13+H14 | I15: =I10+I11+I12+I13+I14 | J15: =J10+J11+J12+J13+J14 | ... N15: =N10+N11+N12+N13+N14 | O15: =SUM(C15:N15)
A16: NET CASH FLOW | C16: =C8-C15 | D16: =D8-D15 | E16: =E8-E15 | F16: =F8-F15 | G16: =G8-G15 | H16: =H8-H15 | I16: =I8-I15 | J16: =J8-J15 | ... N16: =N8-N15 | O16: =SUM(C16:N16)
A17: ENDING CASH BALANCE | C17: =C4+C16 | D17: =D4+D16 | E17: =E4+E16 | F17: =F4+F16 | G17: =G4+G16 | H17: =H4+H16 | I17: =I4+I16 | J17: =J4+J16 | ... N17: =N4+N16 | O17: =N17

Sheet Break-Even Analysis
A1: HAVANA CLEANING — BREAK-EVEN ANALYSIS
A2: All calculations reference Inputs and Operating Expenses sheets.
A4: COMPONENT | B4: DESCRIPTION | C4: MONTHLY AMOUNT | D4: NOTES
A5: MONTHLY FIXED COSTS
A6: Base Labor (owner + 1 cleaner) | B6: Min staffing | C6: ='Inputs'!$B$17*'Inputs'!$B$22 | D6: 1 cleaner at entry rate
A7: Payroll Taxes on Base Labor | B7: FICA | C7: =C6*'Inputs'!$B$31 | D7: Applied to cleaner wages
A8: Workers Comp on Base Labor | B8: WC | C8: =C6*'Inputs'!$B$32 | D8: Applied to cleaner wages
A9: Benefits (1 FT employee) | B9: Health stipend | C9: ='Inputs'!$B$33 | D9: Per FT employee
A10: Vehicle Insurance | B10: 1 van | C10: ='Inputs'!$B$37 | D10: Monthly premium
A11: Vehicle Maintenance | B11: 1 van | C11: ='Inputs'!$B$38 | D11: Monthly avg
A12: General Liability Insurance | B12: Monthly | C12: ='Inputs'!$B$48 | D12: Required
A13: Workers Comp Insurance | B13: Monthly | C13: ='Inputs'!$B$49 | D13: Required
A14: Surety Bond | B14: Monthly | C14: ='Inputs'!$B$50 | D14: Janitorial bond
A15: Technology & Software | B15: Monthly total | C15: ='Inputs'!$B$53+'Inputs'!$B$54+'Inputs'!$B$55+'Inputs'!$B$56+'Inputs'!$B$57+'Inputs'!$B$58 | D15: All subscriptions
A16: Office & Admin | B16: Monthly total | C16: ='Inputs'!$B$63+'Inputs'!$B$64+'Inputs'!$B$65+'Inputs'!$B$66 | D16: Overhead
A17: Marketing (minimum) | B17: Base ad spend | C17: 1200 | D17: Editable minimum
A18: Contingency | B18: Buffer | C18: 200 | D18: Editable buffer
A19: TOTAL FIXED COSTS / MONTH | C19: =SUM(C6:C18)
A21: VARIABLE COSTS PER JOB
A22: Cleaning Supplies | B22: Consumables | C22: ='Inputs'!$B$43 | D22: Per standard job
A23: Gas/Travel | B23: Per job portion | C23: ='Inputs'!$B$36/3 | D23: $25/day ÷ 3 jobs/day
A24: Stripe Processing | B24: 2.9% + $0.30 | C24: =150*'Inputs'!$B$59+'Inputs'!$B$60 | D24: On ~$150 avg job
A25: Equipment Wear & Tear | B25: Amortized | C25: 2 | D25: Replacement amortization
A26: TOTAL VARIABLE COST / JOB | C26: =SUM(C22:C25)
A28: BREAK-EVEN CALCULATION
A29: Avg Revenue per Job | C29: ='Profit & Loss'!O6/'Revenue Projections'!O15 | D29: Year 1 weighted average
A30: Contribution Margin / Job | C30: =C29-C26 | D30: Revenue - Variable Cost
A31: BREAK-EVEN JOBS / MONTH | C31: =C19/C30 | D31: Fixed Costs ÷ Contribution Margin
A32: BREAK-EVEN REVENUE / MONTH | C32: =C31*C29
A33: BREAK-EVEN JOBS / DAY | C33: =C31/'Inputs'!$B$25 | D33: Jobs ÷ working days/month

Sheet 3-Year Summary
A1: HAVANA CLEANING — 3-YEAR FINANCIAL SUMMARY
A2: Year 1 from P&L. Years 2-3 auto-scale by growth rates on Inputs sheet.
A4: LINE ITEM | B4: YEAR 1 | C4: YEAR 2 | D4: YEAR 3 | E4: 3-YEAR TOTAL
A5: Total Revenue | B5: ='Profit & Loss'!O6 | C5: =B5*(1+'Inputs'!$B$69) | D5: =C5*(1+'Inputs'!$B$70) | E5: =SUM(B5:D5)
A6: Revenue Growth % | B6: — | C6: ='Inputs'!$B$69 | D6: ='Inputs'!$B$70
A7: Total COGS | B7: ='Profit & Loss'!O12 | C7: =B7/B5*C5*0.95 | D7: =C7/C5*D5*0.93 | E7: =SUM(B7:D7)
A8: GROSS PROFIT | B8: =B5-B7 | C8: =C5-C7 | D8: =D5-D7 | E8: =SUM(B8:D8)
A9: Gross Margin % | B9: =IF(B5=0,0,B8/B5) | C9: =IF(C5=0,0,C8/C5) | D9: =IF(D5=0,0,D8/D5)
A10: Operating Expenses (SG&A) | B10: ='Profit & Loss'!O17 | C10: =B10*1.3 | D10: =C10*1.2 | E10: =SUM(B10:D10)
A11: Owner Draw / Salary | B11: ='Inputs'!$B$26 | C11: ='Inputs'!$B$27 | D11: ='Inputs'!$B$28 | E11: =SUM(B11:D11)
A12: NET OPERATING INCOME | B12: =B8-B10-B11 | C12: =C8-C10-C11 | D12: =D8-D10-D11 | E12: =SUM(B12:D12)
A13: Net Margin % | B13: =IF(B5=0,0,B12/B5) | C13: =IF(C5=0,0,C12/C5) | D13: =IF(D5=0,0,D12/D5)
A15: STARTUP INVESTMENT REQUIRED | B15: ='Startup Costs'!E100

Sheet Equipment Checklist
A1: HAVANA CLEANING — EQUIPMENT & SUPPLY CHECKLIST
A3: ITEM | B3: CATEGORY | C3: QTY | D3: UNIT COST | E3: TOTAL | F3: REPLACE FREQUENCY
A4: Commercial Backpack Vacuum | B4: Core Equipment | C4: 3 | D4: 350 | E4: =C4*D4 | F4: Every 3-5 years
A5: HEPA Filter Vacuum | B5: Core Equipment | C5: 1 | D5: 450 | E5: =C5*D5 | F5: Every 3-5 years
A6: Commercial Mop & Bucket System | B6: Core Equipment | C6: 3 | D6: 85 | E6: =C6*D6 | F6: Every 2-3 years
A7: Microfiber Flat Mop System | B7: Core Equipment | C7: 3 | D7: 65 | E7: =C7*D7 | F7: Every 1-2 years
A8: Steam Cleaner (handheld) | B8: Core Equipment | C8: 2 | D8: 120 | E8: =C8*D8 | F8: Every 3-4 years
A9: Extension Pole (telescoping) | B9: Core Equipment | C9: 3 | D9: 35 | E9: =C9*D9 | F9: Every 3-5 years
A10: Step Ladder (aluminum) | B10: Core Equipment | C10: 2 | D10: 75 | E10: =C10*D10 | F10: Every 5+ years
A11: Wet/Dry Shop Vac | B11: Core Equipment | C11: 1 | D11: 180 | E11: =C11*D11 | F11: Every 3-5 years
A12: Spray Bottles (color-coded) | B12: Cleaning Tools | C12: 24 | D12: 3 | E12: =C12*D12 | F12: Every 6-12 months
A13: Scrub Brush Set | B13: Cleaning Tools | C13: 4 | D13: 22 | E13: =C13*D13 | F13: Every 6-12 months
A14: Squeegee (professional) | B14: Cleaning Tools | C14: 3 | D14: 28 | E14: =C14*D14 | F14: Every 1-2 years
A15: Grout Brush Set | B15: Cleaning Tools | C15: 4 | D15: 15 | E15: =C15*D15 | F15: Every 6-12 months
... A42: Dash Camera | B42: Vehicle | C42: 1 | D42: 150 | E42: =C42*D42 | F42: Every 2-3 years
A44: TOTAL EQUIPMENT INVESTMENT | E44: =SUM(E4:E42)

Sheet KPI Dashboard
A1: HAVANA CLEANING — KEY PERFORMANCE INDICATORS
A2: All KPIs auto-calculate from other sheets.
A4: KPI METRIC | B4: YEAR 1 VALUE | C4: FORMULA SOURCE
A5: FINANCIAL KPIs
A6: Total Annual Revenue | B6: ='Profit & Loss'!O6 | C6: P&L Annual Revenue
A7: Total COGS | B7: ='Profit & Loss'!O12 | C7: P&L Annual COGS
A8: Gross Profit | B8: ='Profit & Loss'!O13 | C8: Revenue - COGS
A9: Gross Margin % | B9: ='Profit & Loss'!O14 | C9: Gross Profit / Revenue
A10: Total Operating Expenses | B10: ='Profit & Loss'!O17 | C10: P&L Annual SG&A
A11: Net Operating Income | B11: ='Profit & Loss'!O19 | C11: Gross Profit - OpEx
A12: Net Margin % | B12: ='Profit & Loss'!O20 | C12: Net Income / Revenue
A13: Ending Cash Balance | B13: ='Cash Flow'!N17 | C13: Cash Flow M12 ending
A15: OPERATIONAL KPIs
A16: Total Jobs Completed (Year 1) | B16: ='Revenue Projections'!O15 | C16: Revenue sheet annual jobs
A17: Average Revenue per Job | B17: ='Profit & Loss'!O6/'Revenue Projections'!O15 | C17: Revenue / Total Jobs
A18: Jobs per Working Day (avg) | B18: ='Revenue Projections'!O15/('Inputs'!$B$25*12) | C18: Annual jobs / working days
A19: Break-Even Jobs/Month | B19: ='Break-Even Analysis'!C31 | C19: From break-even sheet
A20: Break-Even Revenue/Month | B20: ='Break-Even Analysis'!C32 | C20: From break-even sheet
A21: Year-End Headcount | B21: ='Employee Projections'!N11 | C21: M12 headcount
A22: Revenue per Employee | B22: ='Profit & Loss'!O6/'Employee Projections'!N11 | C22: Revenue / headcount
A23: Startup Investment | B23: ='Startup Costs'!E100 | C23: Startup Costs sheet total
A25: 3-YEAR OUTLOOK
A26: Year 2 Projected Revenue | B26: ='3-Year Summary'!C5 | C26: Year 1 x (1 + growth rate)
A27: Year 3 Projected Revenue | B27: ='3-Year Summary'!D5 | C27: Year 2 x (1 + growth rate)
A28: Year 2 Net Income | B28: ='3-Year Summary'!C12 | C28: 3-Year Summary
A29: Year 3 Net Income | B29: ='3-Year Summary'!D12 | C29: 3-Year Summary
A30: 3-Year Total Revenue | B30: ='3-Year Summary'!E5 | C30: Sum of 3 years
A31: 3-Year Total Net Income | B31: ='3-Year Summary'!E12 | C31: Sum of 3 years
